Preparing test test_single_throw_exception
OperationNumber: Op1
Dependencies: 0
MaxRetries: 0
NumberOfFailures: 0
CallDelays: empty
RetryDelay: 0
RevertMaxRetries: 0
RevertNumberOfFailures: 0
RevertCallDelay: empty
RevertRetryDelay: 0
ValidateFunctionResults: empty
RevertValidateFunctionResults: empty
CallCounter: 0
RevertCallCounter: 0
ValidateCallCounter: 0
RevertValidateCallCounter: 0
Deactivate: empty
ThrowException: 1
ValidateThrowException: empty
RevertThrowException: empty
RevertValidateThrowException: empty
HasReportFail: False
HasRevert: False
HasValidate: False
HasRevertValidate: False

OnRevertedCallback: Reverted.
Run Log:
[*time*][Op1]: Start Executing Op1
[*time*][Op1]: Error when calling Op1. Error: Throwing exception on call 1. Retry in 00:00:00 seconds
[*time*][Op1]: No reminder set for Op1. Taking failure action
[*time*][Op1]: Op1 Failed. Retries exhausted.
[*time*][Op1]: Start Executing Revert Op1
[*time*][Op1]: No undo operation for Op1. Marking as reverted


OnSagaCompleted: Id: test Status: Reverted

*** Telemetry ***
1: StartSaga - SagaID: test, Type: SagaOperations
2: StartOperation - SagaID: test, Operation: Op1
3: Exception - SagaID: test, Context: Error when calling Op1, Exception: Throwing exception on call 1
4: EndOperation - SagaID: test, Operation: Op1, Outcome: Failed
5: EndSaga - SagaID: test, Outcome: Reverted
