Preparing test test_single_throw_exception_and_exponential_retry
OperationNumber: Op1
Dependencies: 0
MaxRetries: 1
NumberOfFailures: 0
CallDelays: empty
RetryDelay: 0
RevertMaxRetries: 0
RevertNumberOfFailures: 0
RevertCallDelay: empty
RevertRetryDelay: 0
ValidateFunctionResults: empty
RevertValidateFunctionResults: empty
CallCounter: 0
RevertCallCounter: 0
ValidateCallCounter: 0
RevertValidateCallCounter: 0
Deactivate: empty
ThrowException: 1
ValidateThrowException: empty
RevertThrowException: empty
RevertValidateThrowException: empty
HasReportFail: False
HasRevert: False
HasValidate: False
HasRevertValidate: False

Calling Op1: Success True
OnSuccessCompletionCallback: Success.
Run Log:
[*time*][Op1]: Start Executing Op1
[*time*][Op1]: Registering reminder Op1:Retry for Op1 with interval 00:00:02
[*time*][Op1]: Error when calling Op1. Error: Throwing exception on call 1. Retry in 00:00:02 seconds
[*time*][Op1]: Wake by a reminder
[*time*][Op1]: The validate function does not exist or raised an exception, retry Op1 action
[*time*][Op1]: Retry Op1. Retry count: 1
[*time*][Op1]: Start Executing Op1
[*time*][Op1]: Registering reminder Op1:Retry for Op1 with interval 00:00:03
[*time*][Op1]: Op1 Success


OnSagaCompleted: Id: test Status: Succeeded

*** Telemetry ***
1: StartSaga - SagaID: test, Type: SagaOperations
2: StartOperation - SagaID: test, Operation: Op1
3: Exception - SagaID: test, Context: Error when calling Op1, Exception: Throwing exception on call 1
4: RetryAttempt - SagaID: test, Operation: Op1, Attempt: 1
5: StartOperation - SagaID: test, Operation: Op1
6: EndOperation - SagaID: test, Operation: Op1, Outcome: Succeeded
7: EndSaga - SagaID: test, Outcome: Succeeded
